Workbook
Name BTC_Held: 'Inputs'!$B$6
Name BTC_AvgCost: 'Inputs'!$B$7
Name BTC_Spot: 'Inputs'!$B$8
Name EURUSD_Spot: 'Inputs'!$B$9
Name MSTR_Shares: 'Inputs'!$B$10
Name MSTR_Price: 'Inputs'!$B$11
Name MSTR_ADV: 'Inputs'!$B$12
Name USD_Reserve: 'Inputs'!$B$14
Name Reserve_Min_Months: 'Inputs'!$B$15
Name USD_Cash: 'Inputs'!$B$16
Name BTC_Monetization_Cap: 'Inputs'!$B$17
Name ATM_MSTR_Remaining: 'Inputs'!$B$18
Name ATM_STRF: 'Inputs'!$B$19
Name ATM_STRC: 'Inputs'!$B$20
Name ATM_STRK: 'Inputs'!$B$21
Name ATM_STRD: 'Inputs'!$B$22
Name Pref_Buyback_Remaining: 'Inputs'!$B$23
Name Debt_Principal: 'Inputs'!$B$25
Name Conv_Coupon_Semi: 'Inputs'!$B$26
Name Other_Debt_Interest: 'Inputs'!$B$27
Name Notional_STRF_In: 'Inputs'!$B$29
Name STRC_Notional_0630: 'Inputs'!$B$30
Name Notional_STRK_In: 'Inputs'!$B$31
Name Notional_STRD_In: 'Inputs'!$B$32
Name Notional_STRE_EUR: 'Inputs'!$B$33
Name STRC_LiqPref: 'Inputs'!$B$34
Name STRC_Repurchased_Shares: 'Inputs'!$B$35
Name STRC_Repurchased_Since_Aug23: 'Inputs'!$B$36
Name STRC_Issued_Shares: 'Inputs'!$B$37
Name Rate_STRF: 'Inputs'!$B$38
Name Rate_STRC_Base: 'Inputs'!$B$39
Name Rate_STRK: 'Inputs'!$B$40
Name Rate_STRD: 'Inputs'!$B$41
Name Rate_STRE: 'Inputs'!$B$42
Name Rank_STRF: 'Inputs'!$B$44
Name Rank_STRC: 'Inputs'!$B$45
Name Rank_STRE: 'Inputs'!$B$46
Name Rank_STRK: 'Inputs'!$B$47
Name Rank_STRD: 'Inputs'!$B$48
Name Participation: 'Inputs'!$B$50
Name Trading_Days: 'Inputs'!$B$51
Name mNAV_Floor: 'Inputs'!$B$52
Name Gate_On: 'Inputs'!$B$53
Name ATM_Binding: 'Inputs'!$B$54
Name Include_USD_Cash: 'Inputs'!$B$55
Name Include_BTC_Monetization: 'Inputs'!$B$56
Name STRK_In_Stock: 'Inputs'!$B$57
Name Target_Years: 'Inputs'!$B$58
Name Display_Cap: 'Inputs'!$B$59
Name Mgmt_Annual_Estimate: 'Inputs'!$B$60
Name Recon_Tolerance: 'Inputs'!$B$61
Name STRC_Shares_Now: 'Inputs'!$B$67
Name STRC_Notional_Now: 'Inputs'!$B$68
Name Conv_Principal_Sched: 'Inputs'!$B$78
Name Conv_Coupon_Sched: 'Inputs'!$F$78
Name Conv_Principals: 'Inputs'!$B$72:$B$77
Name Conv_PutDates: 'Inputs'!$E$72:$E$77
Name Conv_Interest_Annual: 'Inputs'!$B$79
Name L_BTC_Chg: 'Scenarios'!$H$5
Name L_BTC: 'Scenarios'!$H$6

Sheet Dashboard
A1: Can Strategy keep paying its preferreds?
A2: Coverage of STRF, STRC, STRE, STRK and STRD from the USD Reserve, common stock sales and bitcoin. Public filings only; not investment advice.
A4: Scenario (pick one) | B4: Base | D4: Model checks | E4: =Checks_Status
A5: ="Live: BTC $"&TEXT(L_BTC,"#,##0")&" | mNAV "&TEXT(L_mNAV,"0.00")&"x | STRC "&TEXT(L_STRC,"0.0%")&" | EUR/USD "&TEXT(L_EURUSD,"0.0000")&" | market data as of 2026-10-15"
A7: ="Annual cash charges are $"&TEXT(Charges_Total,"#,##0")&"m, "&TEXT(Div_STRC_Cash/Charges_Total,"0%")&" of it STRC. The Reserve alone covers "&TEXT(Cov_Reserve_Months,"0")&" months. "&IF(Gate_Closed,"Below the "&TEXT(mNAV_Floor,"0.0")&"x mNAV floor no common stock is sold, so that is all the cover there is.","With common stock sales: "&IF(Cov_Years_Total>=Display_Cap,"self-funding.",TEXT(Cov_Years_Total,"0.0")&" years."))&" Bitcoin covers debt + preferred "&TEXT(BTC_Cover_Total,"0.0")&"x and would have to fall to $"&TEXT(BE_BTC_1x,"#,##0")&" for 1.0x."
A11: Cash and stock | B11: Live | D11: Bitcoin and debt | F11: Live
A12: Annual cash fixed charges ($m) | B12: =Charges_Total | D12: Bitcoin cover of debt + preferred | F12: =BTC_Cover_Total
A13: USD Reserve available ($m) | B13: =Reserve_Live | D13: BTC price where cover = 1.0x | F13: =BE_BTC_1x
A14: Reserve alone covers | B14: =Cov_Reserve_Months | D14: Fall from live BTC price to 1.0x | F14: =BE_Drawdown_1x
A15: Headroom above 12-month policy ($m) | B15: =Reserve_Headroom | D15: BTC to sell for one year of charges | F15: =BTC_Per_Year
A16: Common stock sales capacity per year ($m) | B16: =Common_Per_Year | D16: ...as a share of holdings | F16: =BTC_Pct_Year
A17: Reserve + common stock cover | B17: =Cov_Years_Total | D17: ="BTC price for "&Target_Years&" yrs of cover" | F17: =BE_BTC_Target
A18: Dilution to fund one year of charges | B18: =Dilution_Year | D18: Convertible puts, Oct 2026-Sep 2028 ($m) | F18: =Puts_In_Window
A20: Coverage down the seniority stack (live)
A21: Down to and including | B21: Cash charges ($m) | C21: Reserve alone | D21: Reserve + common | E21: BTC cover
A22: =Coverage!A5 | B22: =Coverage!B5 | C22: =Coverage!C5 | D22: =Coverage!E5 | E22: =Coverage!G5
A23: =Coverage!A6 | B23: =Coverage!B6 | C23: =Coverage!C6 | D23: =Coverage!E6 | E23: =Coverage!G6
A24: =Coverage!A7 | B24: =Coverage!B7 | C24: =Coverage!C7 | D24: =Coverage!E7 | E24: =Coverage!G7
A25: =Coverage!A8 | B25: =Coverage!B8 | C25: =Coverage!C8 | D25: =Coverage!E8 | E25: =Coverage!G8
A26: =Coverage!A9 | B26: =Coverage!B9 | C26: =Coverage!C9 | D26: =Coverage!E9 | E26: =Coverage!G9
A27: =Coverage!A10 | B27: =Coverage!B10 | C27: =Coverage!C10 | D27: =Coverage!E10 | E27: =Coverage!G10
A28: Cumulative: the STRC row means the Reserve also pays debt interest and STRF, which rank ahead of it.
A30: All five scenarios side by side (independent of the selector)
A31: Scenario | B31: Base | C31: Bear | D31: Severe | E31: Bull | F31: Custom
A32: BTC price | B32: =Scenarios!B6 | C32: =Scenarios!C6 | D32: =Scenarios!D6 | E32: =Scenarios!E6 | F32: =Scenarios!F6
A33: mNAV | B33: =Scenarios!B7 | C33: =Scenarios!C7 | D33: =Scenarios!D7 | E33: =Scenarios!E7 | F33: =Scenarios!F7
A34: STRC rate | B34: =Scenarios!B8 | C34: =Scenarios!C8 | D34: =Scenarios!D8 | E34: =Scenarios!E8 | F34: =Scenarios!F8
A35: Annual cash charges ($m) | B35: =Charges_Total-Div_STRC_Cash-Div_STRE_Cash+STRC_Notional_Now*Scenarios!B8+Notional_STRE_EUR*Scenarios!B10*Rate_STRE | C35: =Charges_Total-Div_STRC_Cash-Div_STRE_Cash+STRC_Notional_Now*Scenarios!C8+Notional_STRE_EUR*Scenarios!C10*Rate_STRE | D35: =Charges_Total-Div_STRC_Cash-Div_STRE_Cash+STRC_Notional_Now*Scenarios!D8+Notional_STRE_EUR*Scenarios!D10*Rate_STRE | E35: =Charges_Total-Div_STRC_Cash-Div_STRE_Cash+STRC_Notional_Now*Scenarios!E8+Notional_STRE_EUR*Scenarios!E10*Rate_STRE | F35: =Charges_Total-Div_STRC_Cash-Div_STRE_Cash+STRC_Notional_Now*Scenarios!F8+Notional_STRE_EUR*Scenarios!F10*Rate_STRE
A36: Reserve available ($m) | B36: =USD_Reserve+IF(Include_USD_Cash="Yes",USD_Cash,0)+IF(Include_BTC_Monetization="Yes",MIN(BTC_Monetization_Cap,BTC_Held*B32/1000000),0) | C36: =USD_Reserve+IF(Include_USD_Cash="Yes",USD_Cash,0)+IF(Include_BTC_Monetization="Yes",MIN(BTC_Monetization_Cap,BTC_Held*C32/1000000),0) | D36: =USD_Reserve+IF(Include_USD_Cash="Yes",USD_Cash,0)+IF(Include_BTC_Monetization="Yes",MIN(BTC_Monetization_Cap,BTC_Held*D32/1000000),0) | E36: =USD_Reserve+IF(Include_USD_Cash="Yes",USD_Cash,0)+IF(Include_BTC_Monetization="Yes",MIN(BTC_Monetization_Cap,BTC_Held*E32/1000000),0) | F36: =USD_Reserve+IF(Include_USD_Cash="Yes",USD_Cash,0)+IF(Include_BTC_Monetization="Yes",MIN(BTC_Monetization_Cap,BTC_Held*F32/1000000),0)
A37: Preferred notional ($m) | B37: =Pref_Notional_Total-Notional_STRE+Notional_STRE_EUR*Scenarios!B10 | C37: =Pref_Notional_Total-Notional_STRE+Notional_STRE_EUR*Scenarios!C10 | D37: =Pref_Notional_Total-Notional_STRE+Notional_STRE_EUR*Scenarios!D10 | E37: =Pref_Notional_Total-Notional_STRE+Notional_STRE_EUR*Scenarios!E10 | F37: =Pref_Notional_Total-Notional_STRE+Notional_STRE_EUR*Scenarios!F10
A38: Implied MSTR market cap ($m) | B38: =MAX(0,B33*BTC_Held*B32/1000000-Debt_Principal-B37+Cash_For_EV) | C38: =MAX(0,C33*BTC_Held*C32/1000000-Debt_Principal-C37+Cash_For_EV) | D38: =MAX(0,D33*BTC_Held*D32/1000000-Debt_Principal-D37+Cash_For_EV) | E38: =MAX(0,E33*BTC_Held*E32/1000000-Debt_Principal-E37+Cash_For_EV) | F38: =MAX(0,F33*BTC_Held*F32/1000000-Debt_Principal-F37+Cash_For_EV)
A39: Common sales per year ($m) | B39: =IF(AND(Gate_On="Yes",B33<mNAV_Floor),0,Scenarios!B12*B38/MSTR_Shares*Scenarios!B13*Trading_Days) | C39: =IF(AND(Gate_On="Yes",C33<mNAV_Floor),0,Scenarios!C12*C38/MSTR_Shares*Scenarios!C13*Trading_Days) | D39: =IF(AND(Gate_On="Yes",D33<mNAV_Floor),0,Scenarios!D12*D38/MSTR_Shares*Scenarios!D13*Trading_Days) | E39: =IF(AND(Gate_On="Yes",E33<mNAV_Floor),0,Scenarios!E12*E38/MSTR_Shares*Scenarios!E13*Trading_Days) | F39: =IF(AND(Gate_On="Yes",F33<mNAV_Floor),0,Scenarios!F12*F38/MSTR_Shares*Scenarios!F13*Trading_Days)
A40: Reserve alone (months) | B40: =B36/B35*12 | C40: =C36/C35*12 | D40: =D36/D35*12 | E40: =E36/E35*12 | F40: =F36/F35*12
A41: Reserve + common (years) | B41: =MIN(Display_Cap,IF(AND(B39<B35,B39*B36/(B35-B39)<=ATM_Cap),B36/(B35-B39),(B36+ATM_Cap)/B35)) | C41: =MIN(Display_Cap,IF(AND(C39<C35,C39*C36/(C35-C39)<=ATM_Cap),C36/(C35-C39),(C36+ATM_Cap)/C35)) | D41: =MIN(Display_Cap,IF(AND(D39<D35,D39*D36/(D35-D39)<=ATM_Cap),D36/(D35-D39),(D36+ATM_Cap)/D35)) | E41: =MIN(Display_Cap,IF(AND(E39<E35,E39*E36/(E35-E39)<=ATM_Cap),E36/(E35-E39),(E36+ATM_Cap)/E35)) | F41: =MIN(Display_Cap,IF(AND(F39<F35,F39*F36/(F35-F39)<=ATM_Cap),F36/(F35-F39),(F36+ATM_Cap)/F35))
A42: Dilution for one year of charges | B42: =IF(B39=0,"gate",IF(B38=0,"wiped out",B35/B38)) | C42: =IF(C39=0,"gate",IF(C38=0,"wiped out",C35/C38)) | D42: =IF(D39=0,"gate",IF(D38=0,"wiped out",D35/D38)) | E42: =IF(E39=0,"gate",IF(E38=0,"wiped out",E35/E38)) | F42: =IF(F39=0,"gate",IF(F38=0,"wiped out",F35/F38))
A43: BTC cover of debt + preferred | B43: =BTC_Held*B32/1000000/(Debt_Principal+B37) | C43: =BTC_Held*C32/1000000/(Debt_Principal+C37) | D43: =BTC_Held*D32/1000000/(Debt_Principal+D37) | E43: =BTC_Held*E32/1000000/(Debt_Principal+E37) | F43: =BTC_Held*F32/1000000/(Debt_Principal+F37)
A44: Each column reruns the whole chain from its own levers on Scenarios. The highlighted column is the selected one and must equal the live figures (see Checks).

Sheet README
A1: README
A2: Strategy preferred coverage model. Built from public filings; not investment advice.
A5: The question
A6: For STRF, STRC, STRE, STRK and STRD: how long can Strategy pay its fixed charges from the USD Reserve, from common stock it can still sell, and from bitcoin? At what bitcoin price and mNAV does each source stop being enough?
A8: How to use it
A9: 1. Dashboard: pick a scenario in the yellow cell B4. Every sheet recalculates. The side-by-side table shows all five scenarios at once.
A10: 2. Scenarios: edit the blue levers for Bear, Severe, Bull or Custom. Base always links to the latest Inputs.
A11: 3. Inputs: refresh after each weekly 8-K or 10-Q. Each row carries its as-of date and source. Yellow cells are judgement calls; the Yes/No toggles change what counts as cash.
A12: 4. Checks: every row should read PASS. The Dashboard shows the overall status next to the selector.
A14: Sheet map (data flows one way)
A15: Inputs + Scenarios -> Instruments -> Obligations -> Liquidity -> Coverage -> Stress -> Dashboard. Checks reads from all of them.
A17: Colour and format key
... A52: v1.0, built 2026-10-16 from inputs as of 2026-10-15. Refresh after Strategy's Q3 2026 10-Q.

Sheet Inputs
A1: Inputs
A2: Every hard-coded number lives here. Blue = input, yellow fill = judgement call. Market data as of 2026-10-15.
A4: Input | B4: Value | C4: Unit | D4: As of | E4: Source | F4: Note
A5: Bitcoin and market data (point-in-time; refresh before use)
A6: Bitcoin held | B6: 848250 | C6: BTC | D6: 2026-10-11 | E6: https://www.sec.gov/Archives/edgar/data/1050446/000119312526419726/mstr-ex99_1.htm | F6: Weekly 8-K, Exhibit 99.1
A7: Average purchase price | B7: 75444 | C7: $/BTC | D7: 2026-10-11 | E7: https://www.sec.gov/Archives/edgar/data/1050446/000119312526419726/mstr-ex99_1.htm | F7: Context only
A8: BTC price (Base) | B8: 82131 | C8: $/BTC | D8: 2026-10-15 | E8: https://api.exchange.coinbase.com/products/BTC-USD/candles | F8: Coinbase BTC-USD daily close, Oct 15 2026 (UTC). Secondary market data
A9: EUR/USD (Base) | B9: 1.1253 | C9: USD per EUR | D9: 2026-10-16 | E9: https://www.ecb.europa.eu/stats/policy_and_exchange_rates/euro_reference_exchange_rates/html/eurofxref-graph-usd.en.html | F9: ECB euro reference rate
A10: MSTR shares outstanding, Class A + B | B10: 421.761 | C10: m shares | D10: 2026-10-11 | E10: https://www.sec.gov/Archives/edgar/data/0001050446/000105044626000044/mstr-20260630.htm | F10: Estimate: 364.586m Class A (10-Q cover, Jul 24) + 37.536m sold via ATM Jul 27-Oct 11 (weekly 8-Ks) + 19.640m Class B. May understate by up to 5.4m (Jul 20-26 week straddles the cover date)
A11: MSTR share price (Base) | B11: 151.29 | C11: $/sh | D11: 2026-10-15 | E11: https://finance.yahoo.com/quote/MSTR/history | F11: Close, Oct 15 2026. Secondary market data
A12: MSTR average daily volume | B12: 22 | C12: m shares/day | D12: 2026-10-15 | E12: https://finance.yahoo.com/quote/MSTR/history | F12: 20-day average, Sep 18-Oct 15 2026, computed from Yahoo Finance history
A13: Company liquidity
A14: USD Reserve (dividends + interest) | B14: 4880 | C14: $m | D14: 2026-10-11 | E14: https://www.sec.gov/Archives/edgar/data/1050446/000119312526419726/mstr-ex99_1.htm | F14: Ring-fenced for preferred dividends and debt interest (Jun 29 policy)
A15: Reserve policy minimum | B15: 12 | C15: months | D15: 2026-06-29 | E15: https://www.sec.gov/Archives/edgar/data/1050446/000119312526286871/mstr-20260629.htm | F15: Management must hold at least 12 months of expected dividends + interest; going lower needs board approval
A16: USD Cash (general treasury) | B16: 640.5 | C16: $m | D16: 2026-10-11 | E16: https://www.sec.gov/Archives/edgar/data/1050446/000119312526419726/mstr-ex99_1.htm | F16: Flexible pool created Aug 24 2026 (https://www.sec.gov/Archives/edgar/data/1050446/000119312526361845/mstr-20260824.htm). Not ring-fenced
A17: BTC that may be sold into the Reserve | B17: 1250 | C17: $m | D17: 2026-06-29 | E17: https://www.sec.gov/Archives/edgar/data/1050446/000119312526286871/mstr-20260629.htm | F17: BTC Monetization Program: up to $1.25B of BTC sales may top up the Reserve
A18: MSTR ATM capacity remaining | B18: 18807.6 | C18: $m | D18: 2026-10-11 | E18: https://www.sec.gov/Archives/edgar/data/1050446/000119312526419726/mstr-ex99_1.htm | F18: Registered capacity, not demand
A19: STRF ATM capacity remaining | B19: 1619.3 | C19: $m | D19: 2026-10-11 | E19: https://www.sec.gov/Archives/edgar/data/1050446/000119312526419726/mstr-ex99_1.htm | F19: No preferred ATM sales Jun 22-Oct 11
A20: STRC ATM capacity remaining | B20: 17510.8 | C20: $m | D20: 2026-10-11 | E20: https://www.sec.gov/Archives/edgar/data/1050446/000119312526419726/mstr-ex99_1.htm | F20: Policy: no STRC issuance below $100 stated amount (10-Q)
A21: STRK ATM capacity remaining | B21: 2100 | C21: $m | D21: 2026-10-11 | E21: https://www.sec.gov/Archives/edgar/data/1050446/000119312526419726/mstr-ex99_1.htm
A22: STRD ATM capacity remaining | B22: 4014.8 | C22: $m | D22: 2026-10-11 | E22: https://www.sec.gov/Archives/edgar/data/1050446/000119312526419726/mstr-ex99_1.htm
A23: Preferred buyback authorization remaining | B23: 354.8 | C23: $m | D23: 2026-10-11 | E23: https://www.sec.gov/Archives/edgar/data/1050446/000119312526419726/mstr-ex99_1.htm | F23: Of $2.0B (raised from $1.0B on Sep 8 2026: https://www.sec.gov/Archives/edgar/data/1050446/000119312526384402/mstr-20260831.htm)
A24: Debt
A25: Debt principal (convertibles + other secured) | B25: 6750 | C25: $m | D25: 2026-06-30 | E25: https://www.sec.gov/Archives/edgar/data/0001050446/000105044626000044/mstr-20260630.htm | F25: Convertible schedule below sums to $6,713.7m; ~$40m other secured debt
A26: Convertible coupon per semi-annual period | B26: 17.3 | C26: $m | D26: 2026-06-30 | E26: https://www.sec.gov/Archives/edgar/data/0001050446/000105044626000044/mstr-20260630.htm | F26: Filed figure; cross-checked against the schedule below
A27: Other secured debt interest per year | B27: 2 | C27: $m | D27: 2026-06-30 | E27: https://www.sec.gov/Archives/edgar/data/0001050446/000105044626000044/mstr-20260630.htm | F27: Estimate: ~$40m at 5.2% and SOFR + 4.24%
A28: Preferred stock terms
A29: STRF notional | B29: 1283.969 | C29: $m | D29: 2026-06-30 | E29: https://www.sec.gov/Archives/edgar/data/0001050446/000105044626000044/mstr-20260630.htm | F29: No STRF buybacks or issuance since
A30: STRC notional, Jun 30 2026 | B30: 10489.47 | C30: $m | D30: 2026-06-30 | E30: https://www.sec.gov/Archives/edgar/data/0001050446/000105044626000044/mstr-20260630.htm | F30: 104,894,705 shares; rolled forward in the bridge below
A31: STRK notional | B31: 1402.074 | C31: $m | D31: 2026-06-30 | E31: https://www.sec.gov/Archives/edgar/data/0001050446/000105044626000044/mstr-20260630.htm
A32: STRD notional | B32: 1402.422 | C32: $m | D32: 2026-06-30 | E32: https://www.sec.gov/Archives/edgar/data/0001050446/000105044626000044/mstr-20260630.htm
A33: STRE notional | B33: 775 | C33: EUR m | D33: 2026-06-30 | E33: https://www.sec.gov/Archives/edgar/data/0001050446/000105044626000044/mstr-20260630.htm | F33: 7,750,000 shares x EUR 100 stated amount
A34: STRC stated amount per share | B34: 100 | C34: $/sh | D34: 2026-06-30 | E34: https://www.sec.gov/Archives/edgar/data/0001050446/000105044626000044/mstr-20260630.htm
A35: STRC shares repurchased Jul 1-Oct 11 | B35: 16.973269 | C35: m shares | D35: 2026-10-11 | E35: https://www.sec.gov/Archives/edgar/data/1050446/000119312526419726/mstr-ex99_1.htm | F35: Sum of 13 weekly 8-Ks; $1,645.2m spent = $2.0B authorized - $354.8m remaining
A36: ...of which after Aug 23 | B36: 11.800244 | C36: m shares | D36: 2026-10-11 | E36: https://www.sec.gov/Archives/edgar/data/1050446/000119312526419726/mstr-ex99_1.htm | F36: Used to reconcile to management's Aug 23 figure
A37: STRC shares issued via ATM since Jun 30 | B37: 0 | C37: m shares | D37: 2026-10-11 | E37: https://www.sec.gov/Archives/edgar/data/1050446/000119312526419726/mstr-ex99_1.htm | F37: ATM capacity unchanged in every weekly 8-K
A38: STRF dividend rate | B38: 0.1 | C38: % p.a. | D38: 2026-06-30 | E38: https://www.sec.gov/Archives/edgar/data/0001050446/000105044626000044/mstr-20260630.htm | F38: Fixed. Unpaid dividends compound at a rate that steps up 1% a period to 18%
A39: STRC dividend rate (Base) | B39: 0.12 | C39: % p.a. | D39: 2026-10-16 | E39: https://www.sec.gov/Archives/edgar/data/1050446/000119312526423400/mstr-20261015.htm | F39: Reset monthly; management will recommend 12% until STRC trades near $100
A40: STRK dividend rate | B40: 0.08 | C40: % p.a. | D40: 2026-06-30 | E40: https://www.sec.gov/Archives/edgar/data/0001050446/000105044626000044/mstr-20260630.htm | F40: Fixed. Payable in cash, MSTR Class A shares, or both
A41: STRD dividend rate | B41: 0.1 | C41: % p.a. | D41: 2026-06-30 | E41: https://www.sec.gov/Archives/edgar/data/0001050446/000105044626000044/mstr-20260630.htm | F41: Fixed. Non-cumulative
...

Sheet Scenarios
A1: Scenarios
A2: Pick a case on the Dashboard (cell B4). Base links to Inputs; other columns are blue levers. Live feeds every calculation.
A4: Lever | B4: Base | C4: Bear | D4: Severe | E4: Bull | F4: Custom | H4: Live | I4: What it means
A5: BTC change vs Base price | B5: 0 | C5: -0.5 | D5: -0.7 | E5: 0.5 | F5: 0 | H5: =INDEX(B5:F5,MATCH(Scenario_Select,$B$4:$F$4,0)) | I5: Bear and Severe test large drawdowns
A6: BTC price | B6: =BTC_Spot*(1+B5) | C6: =BTC_Spot*(1+C5) | D6: =BTC_Spot*(1+D5) | E6: =BTC_Spot*(1+E5) | F6: =BTC_Spot*(1+F5) | H6: =INDEX(B6:F6,MATCH(Scenario_Select,$B$4:$F$4,0)) | I6: Base price x (1 + change)
A7: mNAV | B7: =mNAV_Now | C7: 1 | D7: 0.8 | E7: 1.5 | F7: 1.2 | H7: =INDEX(B7:F7,MATCH(Scenario_Select,$B$4:$F$4,0)) | I7: Base uses today's mNAV. Severe sits below the 1.0x floor, so common sales stop
A8: STRC dividend rate | B8: =Rate_STRC_Base | C8: 0.13 | D8: 0.15 | E8: 0.1 | F8: 0.12 | H8: =INDEX(B8:F8,MATCH(Scenario_Select,$B$4:$F$4,0)) | I8: Management resets STRC monthly; stress raises it
A9: EUR/USD change vs Base | B9: 0 | C9: 0 | D9: 0.1 | E9: -0.05 | F9: 0 | H9: =INDEX(B9:F9,MATCH(Scenario_Select,$B$4:$F$4,0)) | I9: A stronger euro raises STRE's dollar cost
A10: EUR/USD | B10: =EURUSD_Spot*(1+B9) | C10: =EURUSD_Spot*(1+C9) | D10: =EURUSD_Spot*(1+D9) | E10: =EURUSD_Spot*(1+E9) | F10: =EURUSD_Spot*(1+F9) | H10: =INDEX(B10:F10,MATCH(Scenario_Select,$B$4:$F$4,0))
A11: MSTR volume vs Base | B11: 1 | C11: 0.8 | D11: 0.6 | E11: 1.2 | F11: 1 | H11: =INDEX(B11:F11,MATCH(Scenario_Select,$B$4:$F$4,0)) | I11: Volume usually dries up in drawdowns
A12: MSTR average daily volume (m shares) | B12: =MSTR_ADV*B11 | C12: =MSTR_ADV*C11 | D12: =MSTR_ADV*D11 | E12: =MSTR_ADV*E11 | F12: =MSTR_ADV*F11 | H12: =INDEX(B12:F12,MATCH(Scenario_Select,$B$4:$F$4,0))
A13: ATM participation (% of volume) | B13: =Participation | C13: 0.1 | D13: 0.05 | E13: 0.1 | F13: 0.1 | H13: =INDEX(B13:F13,MATCH(Scenario_Select,$B$4:$F$4,0)) | I13: Share of daily volume the ATM can sell
A15: Levers are judgement calls, not forecasts. Base uses the latest observed values; Custom is yours to edit.
A16: To stress one lever alone, set the Dashboard selector to Custom and change only that row.

Sheet Instruments
A1: Instruments
A2: One row per preferred, in seniority order. $m. STRE converts at the live EUR/USD rate.
A4: Ticker | B4: Name | C4: Ccy | D4: Rank | E4: Cumulative? | F4: Dividend paid in | G4: Rate (live) | H4: Notional (local m) | I4: FX to USD | J4: Notional ($m) | K4: Annual dividend ($m) | L4: Paid in cash ($m) | M4: Quarterly cash ($m) | N4: Share of cash dividends | O4: ATM remaining ($m) | P4: Payment schedule | Q4: Terms source
A5: STRF | B5: Strife | C5: USD | D5: =Rank_STRF | E5: Yes, compounding + step-up | F5: Cash | G5: =Rate_STRF | H5: =Notional_STRF_In | I5: 1 | J5: =H5*I5 | K5: =J5*G5 | L5: =K5 | M5: =L5/4 | N5: =IF(Pref_Cash_Div_Total=0,0,L5/Pref_Cash_Div_Total) | O5: =ATM_STRF | P5: Quarterly: Mar/Jun/Sep/Dec 31 (record 15th). Daily from Jan 1 2027 if approved Oct 28 | Q5: 10-Q Note 10; 10-K Ex. 4.2
A6: STRC | B6: Stretch | C6: USD | D6: =Rank_STRC | E6: Yes, compounding | F6: Cash | G6: =L_STRC | H6: =STRC_Notional_Now | I6: 1 | J6: =H6*I6 | K6: =J6*G6 | L6: =K6 | M6: =L6/4 | N6: =IF(Pref_Cash_Div_Total=0,0,L6/Pref_Cash_Div_Total) | O6: =ATM_STRC | P6: Semi-monthly (15th and month-end). Daily from Nov 1 2026 if approved Oct 28 | Q6: Amended certificate Jun 15 2026; 8-K Oct 16 2026
A7: STRE | B7: Stream | C7: EUR | D7: =Rank_STRE | E7: Yes, compounding + step-up | F7: Cash (EUR) | G7: =Rate_STRE | H7: =Notional_STRE_EUR | I7: =L_EURUSD | J7: =H7*I7 | K7: =J7*G7 | L7: =K7 | M7: =L7/4 | N7: =IF(Pref_Cash_Div_Total=0,0,L7/Pref_Cash_Div_Total) | O7: n/a (LuxSE) | P7: Quarterly: Mar/Jun/Sep/Dec 31 (record 15th, London). Not in the daily proposal | Q7: STRE certificate Nov 12 2025; 8-K Aug 31 2026. Listed on Luxembourg Euro MTF
A8: STRK | B8: Strike | C8: USD | D8: =Rank_STRK | E8: Yes, compounding | F8: Cash or MSTR shares | G8: =Rate_STRK | H8: =Notional_STRK_In | I8: 1 | J8: =H8*I8 | K8: =J8*G8 | L8: =IF(STRK_In_Stock="Yes",0,K8) | M8: =L8/4 | N8: =IF(Pref_Cash_Div_Total=0,0,L8/Pref_Cash_Div_Total) | O8: =ATM_STRK | P8: Quarterly: Mar/Jun/Sep/Dec 31 (record 15th). Daily from Jan 1 2027 if approved | Q8: 10-Q Note 10; 10-K Ex. 4.2. Converts into 0.1 MSTR
A9: STRD | B9: Stride | C9: USD | D9: =Rank_STRD | E9: No | F9: Cash | G9: =Rate_STRD | H9: =Notional_STRD_In | I9: 1 | J9: =H9*I9 | K9: =J9*G9 | L9: =K9 | M9: =L9/4 | N9: =IF(Pref_Cash_Div_Total=0,0,L9/Pref_Cash_Div_Total) | O9: =ATM_STRD | P9: Quarterly: Mar/Jun/Sep/Dec 31 (record 15th). Daily from Jan 1 2027 if approved | Q9: 10-Q Note 10; 10-K Ex. 4.2
A10: Total | J10: =SUM(J5:J9) | K10: =SUM(K5:K9) | L10: =SUM(L5:L9) | M10: =SUM(M5:M9) | N10: =SUM(N5:N9)
A12: Rank 1 is most senior. All five rank below the convertible notes. STRD is non-cumulative: a skipped STRD dividend is never owed.
A13: STRF and STRE: unpaid dividends compound at a rate that steps up 1% per period to 18%, a strong incentive to pay them first.
A14: Daily dividends: if approved on Oct 28 2026, STRC pays daily from Nov 1 2026 and STRF/STRK/STRD from Jan 1 2027. Timing changes; annual totals do not.

Sheet Obligations
A1: Obligations
A2: Annual cash fixed charges by seniority, then an 8-quarter runway for the USD Reserve under the live scenario.
A4: Claim (most senior first) | B4: Rank | C4: Annual cash ($m) | D4: Cumulative ($m) | E4: Share of total | F4: Principal / notional ($m) | G4: Cumulative claim ($m)
A5: Debt interest | B5: 0 | C5: =Conv_Interest_Annual | D5: =C5 | E5: =C5/Charges_Total | F5: =Debt_Principal | G5: =F5
A6: STRF | B6: =Rank_STRF | C6: =Div_STRF | D6: =D5+C6 | E6: =C6/Charges_Total | F6: =Notional_STRF | G6: =G5+F6
A7: STRC | B7: =Rank_STRC | C7: =Div_STRC | D7: =D6+C7 | E7: =C7/Charges_Total | F7: =Notional_STRC | G7: =G6+F7
A8: STRE | B8: =Rank_STRE | C8: =Div_STRE | D8: =D7+C8 | E8: =C8/Charges_Total | F8: =Notional_STRE | G8: =G7+F8
A9: STRK | B9: =Rank_STRK | C9: =Div_STRK_Cash | D9: =D8+C9 | E9: =C9/Charges_Total | F9: =Notional_STRK | G9: =G8+F9
A10: STRD | B10: =Rank_STRD | C10: =Div_STRD | D10: =D9+C10 | E10: =C10/Charges_Total | F10: =Notional_STRD | G10: =G9+F10
A11: Total cash fixed charges | C11: =SUM(C5:C10) | F11: =SUM(F5:F10)
A12: Rank 0 = debt. STRK shows zero cash if the Inputs toggle pays it in MSTR shares.
A14: Reserve runway, next 8 quarters (live scenario). Common stock proceeds pay charges first.
A15: $m | B15: Q4 2026 | C15: Q1 2027 | D15: Q2 2027 | E15: Q3 2027 | F15: Q4 2027 | G15: Q1 2028 | H15: Q2 2028 | I15: Q3 2028
A16: Quarter starts | B16: 46296 | C16: 46388 | D16: 46478 | E16: 46569 | F16: 46661 | G16: 46753 | H16: 46844 | I16: 46935
A17: Quarter ends | B17: 46387 | C17: 46477 | D17: 46568 | E17: 46660 | F17: 46752 | G17: 46843 | H17: 46934 | I17: 47026
A18: Fixed charges (annual / 4) | B18: =Charges_Total/4 | C18: =Charges_Total/4 | D18: =Charges_Total/4 | E18: =Charges_Total/4 | F18: =Charges_Total/4 | G18: =Charges_Total/4 | H18: =Charges_Total/4 | I18: =Charges_Total/4
A19: MSTR ATM capacity, opening | B19: =ATM_Cap | C19: =MAX(0,B19-B20) | D19: =MAX(0,C19-C20) | E19: =MAX(0,D19-D20) | F19: =MAX(0,E19-E20) | G19: =MAX(0,F19-F20) | H19: =MAX(0,G19-G20) | I19: =MAX(0,H19-H20)
A20: Common stock proceeds used for charges | B20: =MIN(Common_Per_Year/4,B18,B19) | C20: =MIN(Common_Per_Year/4,C18,C19) | D20: =MIN(Common_Per_Year/4,D18,D19) | E20: =MIN(Common_Per_Year/4,E18,E19) | F20: =MIN(Common_Per_Year/4,F18,F19) | G20: =MIN(Common_Per_Year/4,G18,G19) | H20: =MIN(Common_Per_Year/4,H18,H19) | I20: =MIN(Common_Per_Year/4,I18,I19)
A21: Draw on the Reserve | B21: =B18-B20 | C21: =C18-C20 | D21: =D18-D20 | E21: =E18-E20 | F21: =F18-F20 | G21: =G18-G20 | H21: =H18-H20 | I21: =I18-I20
A22: Reserve, opening | B22: =Reserve_Live | C22: =B23 | D22: =C23 | E22: =D23 | F22: =E23 | G22: =F23 | H22: =G23 | I22: =H23
A23: Reserve, closing | B23: =B22-B21 | C23: =C22-C21 | D23: =D22-D21 | E23: =E22-E21 | F23: =F22-F21 | G23: =G22-G21 | H23: =H22-H21 | I23: =I22-I21
A24: Closing Reserve, months of charges | B24: =IF(Charges_Total=0,0,B23/Charges_Total*12) | C24: =IF(Charges_Total=0,0,C23/Charges_Total*12) | D24: =IF(Charges_Total=0,0,D23/Charges_Total*12) | E24: =IF(Charges_Total=0,0,E23/Charges_Total*12) | F24: =IF(Charges_Total=0,0,F23/Charges_Total*12) | G24: =IF(Charges_Total=0,0,G23/Charges_Total*12) | H24: =IF(Charges_Total=0,0,H23/Charges_Total*12) | I24: =IF(Charges_Total=0,0,I23/Charges_Total*12)
A25: Status | B25: =IF(B23<0,"SHORTFALL",IF(B24<Reserve_Min_Months,"Below policy","ok")) | C25: =IF(C23<0,"SHORTFALL",IF(C24<Reserve_Min_Months,"Below policy","ok")) | D25: =IF(D23<0,"SHORTFALL",IF(D24<Reserve_Min_Months,"Below policy","ok")) | E25: =IF(E23<0,"SHORTFALL",IF(E24<Reserve_Min_Months,"Below policy","ok")) | F25: =IF(F23<0,"SHORTFALL",IF(F24<Reserve_Min_Months,"Below policy","ok")) | G25: =IF(G23<0,"SHORTFALL",IF(G24<Reserve_Min_Months,"Below policy","ok")) | H25: =IF(H23<0,"SHORTFALL",IF(H24<Reserve_Min_Months,"Below policy","ok")) | I25: =IF(I23<0,"SHORTFALL",IF(I24<Reserve_Min_Months,"Below policy","ok"))
A26: Convertible principal puttable this quarter (not a Reserve use) | B26: =SUMPRODUCT((Conv_PutDates>=B16)*(Conv_PutDates<=B17)*Conv_Principals) | C26: =SUMPRODUCT((Conv_PutDates>=C16)*(Conv_PutDates<=C17)*Conv_Principals) | D26: =SUMPRODUCT((Conv_PutDates>=D16)*(Conv_PutDates<=D17)*Conv_Principals) | E26: =SUMPRODUCT((Conv_PutDates>=E16)*(Conv_PutDates<=E17)*Conv_Principals) | F26: =SUMPRODUCT((Conv_PutDates>=F16)*(Conv_PutDates<=F17)*Conv_Principals) | G26: =SUMPRODUCT((Conv_PutDates>=G16)*(Conv_PutDates<=G17)*Conv_Principals) | H26: =SUMPRODUCT((Conv_PutDates>=H16)*(Conv_PutDates<=H17)*Conv_Principals) | I26: =SUMPRODUCT((Conv_PutDates>=I16)*(Conv_PutDates<=I17)*Conv_Principals)
A27: Total puttable in the window | B27: =SUM(B26:I26)
A29: Accrual timing: each claim is spread evenly across quarters. Actual dates differ (convertibles pay semi-annually; STRC semi-monthly, daily if approved).
A30: 'Below policy' = closing Reserve under the 12-month minimum. Topping it back up needs equity, BTC sales or board approval to run lower.
A31: Puts are principal, not dividends or interest, so the Reserve is not designated for them. They matter because refinancing them competes for the same equity capacity.

Sheet Liquidity
A1: Liquidity
A2: Three sources of cash, kept separate: the USD Reserve, common stock Strategy can sell, and bitcoin.
A4: Line | B4: Value | C4: Unit | D4: How it is calculated
A5: Today (observed). Gives the Base mNAV
A6: Preferred notional at spot FX | B6: =Notional_STRF_In+STRC_Notional_Now+Notional_STRK_In+Notional_STRD_In+Notional_STRE_EUR*EURUSD_Spot | C6: $m | D6: Inputs only, so the Base mNAV does not move with the selected scenario
A7: MSTR market cap | B7: =MSTR_Price*MSTR_Shares | C7: $m | D7: Price x Class A + Class B shares
A8: Enterprise value | B8: =MSTR_MktCap_Now+Debt_Principal+Pref_Notional_Spot-USD_Reserve-USD_Cash | C8: $m | D8: Market cap + debt + preferred notional - cash (Reserve + USD Cash)
A9: Bitcoin NAV | B9: =BTC_Held*BTC_Spot/1000000 | C9: $m | D9: BTC held x Base BTC price
A10: mNAV = enterprise value / bitcoin NAV | B10: =EV_Now/BTC_NAV_Now | C10: x | D10: Model definition. Strategy changed its own mNAV definition on Jul 23 2026, so its published figure may differ
A11: Live scenario
A12: Bitcoin NAV | B12: =BTC_Held*L_BTC/1000000 | C12: $m | D12: BTC held x live BTC price
A13: Implied enterprise value | B13: =L_mNAV*BTC_NAV_Live | C13: $m | D13: Live mNAV x bitcoin NAV
A14: Cash netted in enterprise value | B14: =USD_Reserve+USD_Cash | C14: $m | D14: Reserve + USD Cash
A15: Implied MSTR market cap | B15: =MAX(0,EV_Live-Debt_Principal-Pref_Notional_Total+Cash_For_EV) | C15: $m | D15: EV - debt - preferred notional + cash, floored at zero. Leverage means equity falls faster than bitcoin
A16: Implied MSTR share price | B16: =MktCap_Live/MSTR_Shares | C16: $/sh | D16: Market cap / shares. Equals the observed price in Base
A17: Source 1: USD Reserve
A18: BTC sales added to the Reserve | B18: =IF(Include_BTC_Monetization="Yes",MIN(BTC_Monetization_Cap,BTC_NAV_Live),0) | C18: $m | D18: BTC Monetization Program, only if the Inputs toggle says Yes
A19: Cash available for fixed charges | B19: =USD_Reserve+IF(Include_USD_Cash="Yes",USD_Cash,0)+BTC_Topup | C19: $m | D19: Reserve + USD Cash (toggle) + BTC top-up (toggle)
A20: Headroom above the 12-month policy minimum | B20: =Reserve_Live-Charges_Total*Reserve_Min_Months/12 | C20: $m | D20: Cash the Reserve can spend before it breaches policy
A21: Source 2: common stock Strategy can sell
A22: MSTR dollar volume per day | B22: =L_ADV*MSTR_Price_Live | C22: $m/day | D22: Live ADV (m shares) x implied price
A23: Volume-limited sales per year | B23: =Dollar_ADV_Live*L_Part*Trading_Days | C23: $m/yr | D23: Dollar ADV x participation x trading days
A24: Below the mNAV floor? | B24: =AND(Gate_On="Yes",L_mNAV<mNAV_Floor) | D24: TRUE stops all common sales: issuing below NAV cuts bitcoin per share
A25: Common stock sales per year | B25: =IF(Gate_Closed,0,Volume_Cap_Year) | C25: $m/yr | D25: Zero when the gate is closed
A26: Registered capacity limiting total sales | B26: =IF(ATM_Binding="Yes",ATM_MSTR_Remaining,1000000000) | C26: $m | D26: Remaining MSTR ATM, or effectively unlimited if the toggle assumes new programs
A27: Shares to issue for one year of charges, % of shares | B27: =IF(Gate_Closed,"no sales (gate)",IF(MktCap_Live=0,"wiped out",Charges_Total/MktCap_Live)) | D27: Charges / implied market cap. Text when no common can be sold
A28: Source 3: bitcoin
A29: BTC to sell for one year of charges | B29: =Charges_Total*1000000/L_BTC | C29: BTC | D29: Charges / live BTC price
A30: ...as a share of holdings | B30: =BTC_Per_Year/BTC_Held
A31: Years of charges the bitcoin could fund | B31: =BTC_NAV_Live/Charges_Total | C31: yrs | D31: Ignores taxes and the price impact of selling

Sheet Coverage
A1: Coverage
A2: How long each source lasts, cumulatively down the seniority stack. A claim is covered only after everything above it is paid.
A4: Down to and including | B4: Cumulative charges ($m) | C4: Reserve alone (months) | D4: Reserve alone (years) | E4: Reserve + common (years) | F4: Cumulative claims ($m) | G4: BTC cover (x) | H4: Charges / BTC NAV
A5: =Obligations!A5 | B5: =Obligations!D5 | C5: =IF(B5=0,Display_Cap*12,MIN(Display_Cap*12,Reserve_Live/B5*12)) | D5: =IF(B5=0,Display_Cap,MIN(Display_Cap,Reserve_Live/B5)) | E5: =MIN(Display_Cap,IF(AND(Common_Per_Year<B5,Common_Per_Year*Reserve_Live/(B5-Common_Per_Year)<=ATM_Cap),Reserve_Live/(B5-Common_Per_Year),(Reserve_Live+ATM_Cap)/B5)) | F5: =Obligations!G5 | G5: =BTC_NAV_Live/F5 | H5: =B5/BTC_NAV_Live
A6: =Obligations!A6 | B6: =Obligations!D6 | C6: =IF(B6=0,Display_Cap*12,MIN(Display_Cap*12,Reserve_Live/B6*12)) | D6: =IF(B6=0,Display_Cap,MIN(Display_Cap,Reserve_Live/B6)) | E6: =MIN(Display_Cap,IF(AND(Common_Per_Year<B6,Common_Per_Year*Reserve_Live/(B6-Common_Per_Year)<=ATM_Cap),Reserve_Live/(B6-Common_Per_Year),(Reserve_Live+ATM_Cap)/B6)) | F6: =Obligations!G6 | G6: =BTC_NAV_Live/F6 | H6: =B6/BTC_NAV_Live
A7: =Obligations!A7 | B7: =Obligations!D7 | C7: =IF(B7=0,Display_Cap*12,MIN(Display_Cap*12,Reserve_Live/B7*12)) | D7: =IF(B7=0,Display_Cap,MIN(Display_Cap,Reserve_Live/B7)) | E7: =MIN(Display_Cap,IF(AND(Common_Per_Year<B7,Common_Per_Year*Reserve_Live/(B7-Common_Per_Year)<=ATM_Cap),Reserve_Live/(B7-Common_Per_Year),(Reserve_Live+ATM_Cap)/B7)) | F7: =Obligations!G7 | G7: =BTC_NAV_Live/F7 | H7: =B7/BTC_NAV_Live
A8: =Obligations!A8 | B8: =Obligations!D8 | C8: =IF(B8=0,Display_Cap*12,MIN(Display_Cap*12,Reserve_Live/B8*12)) | D8: =IF(B8=0,Display_Cap,MIN(Display_Cap,Reserve_Live/B8)) | E8: =MIN(Display_Cap,IF(AND(Common_Per_Year<B8,Common_Per_Year*Reserve_Live/(B8-Common_Per_Year)<=ATM_Cap),Reserve_Live/(B8-Common_Per_Year),(Reserve_Live+ATM_Cap)/B8)) | F8: =Obligations!G8 | G8: =BTC_NAV_Live/F8 | H8: =B8/BTC_NAV_Live
A9: =Obligations!A9 | B9: =Obligations!D9 | C9: =IF(B9=0,Display_Cap*12,MIN(Display_Cap*12,Reserve_Live/B9*12)) | D9: =IF(B9=0,Display_Cap,MIN(Display_Cap,Reserve_Live/B9)) | E9: =MIN(Display_Cap,IF(AND(Common_Per_Year<B9,Common_Per_Year*Reserve_Live/(B9-Common_Per_Year)<=ATM_Cap),Reserve_Live/(B9-Common_Per_Year),(Reserve_Live+ATM_Cap)/B9)) | F9: =Obligations!G9 | G9: =BTC_NAV_Live/F9 | H9: =B9/BTC_NAV_Live
A10: =Obligations!A10 | B10: =Obligations!D10 | C10: =IF(B10=0,Display_Cap*12,MIN(Display_Cap*12,Reserve_Live/B10*12)) | D10: =IF(B10=0,Display_Cap,MIN(Display_Cap,Reserve_Live/B10)) | E10: =MIN(Display_Cap,IF(AND(Common_Per_Year<B10,Common_Per_Year*Reserve_Live/(B10-Common_Per_Year)<=ATM_Cap),Reserve_Live/(B10-Common_Per_Year),(Reserve_Live+ATM_Cap)/B10)) | F10: =Obligations!G10 | G10: =BTC_NAV_Live/F10 | H10: =B10/BTC_NAV_Live
A13: Breakevens (closed form; verify any with Data > What-If Analysis > Goal Seek)
A14: BTC price where bitcoin = debt + all preferred notional | E14: =Claims_Total*1000000/BTC_Held | F14: Below this, the bitcoin is worth less than every claim ahead of common stock
A15: BTC price for 2.0x cover | E15: =2*BE_BTC_1x
A16: Fall from the live BTC price to reach 1.0x | E16: =1-BE_BTC_1x/L_BTC
A17: Common sales per year needed to cover Target_Years | E17: =MAX(0,Charges_Total-Reserve_Live/Target_Years) | F17: Zero means the Reserve alone covers the target
A18: BTC price that still funds Target_Years at the live mNAV | E18: =IF(Common_Needed=0,"Reserve alone covers it",IF((Reserve_Live+ATM_Cap)/Charges_Total<Target_Years,"Not reachable: ATM capacity",IF(Gate_Closed,"Not reachable: below mNAV floor",(Common_Needed*MSTR_Shares/(L_ADV*L_Part*Trading_Days)+Debt_Principal+Pref_Notional_Total-Cash_For_EV)*1000000/(L_mNAV*BTC_Held)))) | F18: Solves Reserve / (charges - common sales) = Target_Years for BTC, holding mNAV, volume and participation at live values
A19: mNAV below which common sales stop | E19: =mNAV_Floor | F19: The gate. Above it, ATM capacity usually binds before volume does
A21: '>=50 yrs' means common sales alone fund the charges up to the display cap. Amber: under Target_Years or under the 12-month Reserve policy. Red: under 1 year or under 1.0x.

Sheet Stress
A1: Stress
A2: Each cell reruns the chain for its BTC price and mNAV, holding the other live levers fixed. Plain formulas: they recalculate in any spreadsheet.
A4: Grid 1. Common stock Strategy can sell per year ($m)
A5: BTC price ↓ mNAV → | B5: 0.6 | C5: 0.8 | D5: 1 | E5: 1.25 | F5: 1.5 | G5: 2 | H5: 2.5
A6: 30000 | B6: =IF(AND(Gate_On="Yes",B$5<mNAV_Floor),0,L_ADV*MAX(0,B$5*BTC_Held*$A6/1000000-Debt_Principal-Pref_Notional_Total+Cash_For_EV)/MSTR_Shares*L_Part*Trading_Days) | C6: =IF(AND(Gate_On="Yes",C$5<mNAV_Floor),0,L_ADV*MAX(0,C$5*BTC_Held*$A6/1000000-Debt_Principal-Pref_Notional_Total+Cash_For_EV)/MSTR_Shares*L_Part*Trading_Days) | D6: =IF(AND(Gate_On="Yes",D$5<mNAV_Floor),0,L_ADV*MAX(0,D$5*BTC_Held*$A6/1000000-Debt_Principal-Pref_Notional_Total+Cash_For_EV)/MSTR_Shares*L_Part*Trading_Days) | E6: =IF(AND(Gate_On="Yes",E$5<mNAV_Floor),0,L_ADV*MAX(0,E$5*BTC_Held*$A6/1000000-Debt_Principal-Pref_Notional_Total+Cash_For_EV)/MSTR_Shares*L_Part*Trading_Days) | F6: =IF(AND(Gate_On="Yes",F$5<mNAV_Floor),0,L_ADV*MAX(0,F$5*BTC_Held*$A6/1000000-Debt_Principal-Pref_Notional_Total+Cash_For_EV)/MSTR_Shares*L_Part*Trading_Days) | G6: =IF(AND(Gate_On="Yes",G$5<mNAV_Floor),0,L_ADV*MAX(0,G$5*BTC_Held*$A6/1000000-Debt_Principal-Pref_Notional_Total+Cash_For_EV)/MSTR_Shares*L_Part*Trading_Days) | H6: =IF(AND(Gate_On="Yes",H$5<mNAV_Floor),0,L_ADV*MAX(0,H$5*BTC_Held*$A6/1000000-Debt_Principal-Pref_Notional_Total+Cash_For_EV)/MSTR_Shares*L_Part*Trading_Days)
A7: 40000 | B7: =IF(AND(Gate_On="Yes",B$5<mNAV_Floor),0,L_ADV*MAX(0,B$5*BTC_Held*$A7/1000000-Debt_Principal-Pref_Notional_Total+Cash_For_EV)/MSTR_Shares*L_Part*Trading_Days) | C7: =IF(AND(Gate_On="Yes",C$5<mNAV_Floor),0,L_ADV*MAX(0,C$5*BTC_Held*$A7/1000000-Debt_Principal-Pref_Notional_Total+Cash_For_EV)/MSTR_Shares*L_Part*Trading_Days) | D7: =IF(AND(Gate_On="Yes",D$5<mNAV_Floor),0,L_ADV*MAX(0,D$5*BTC_Held*$A7/1000000-Debt_Principal-Pref_Notional_Total+Cash_For_EV)/MSTR_Shares*L_Part*Trading_Days) | E7: =IF(AND(Gate_On="Yes",E$5<mNAV_Floor),0,L_ADV*MAX(0,E$5*BTC_Held*$A7/1000000-Debt_Principal-Pref_Notional_Total+Cash_For_EV)/MSTR_Shares*L_Part*Trading_Days) | F7: =IF(AND(Gate_On="Yes",F$5<mNAV_Floor),0,L_ADV*MAX(0,F$5*BTC_Held*$A7/1000000-Debt_Principal-Pref_Notional_Total+Cash_For_EV)/MSTR_Shares*L_Part*Trading_Days) | G7: =IF(AND(Gate_On="Yes",G$5<mNAV_Floor),0,L_ADV*MAX(0,G$5*BTC_Held*$A7/1000000-Debt_Principal-Pref_Notional_Total+Cash_For_EV)/MSTR_Shares*L_Part*Trading_Days) | H7: =IF(AND(Gate_On="Yes",H$5<mNAV_Floor),0,L_ADV*MAX(0,H$5*BTC_Held*$A7/1000000-Debt_Principal-Pref_Notional_Total+Cash_For_EV)/MSTR_Shares*L_Part*Trading_Days)
A8: 50000 | B8: =IF(AND(Gate_On="Yes",B$5<mNAV_Floor),0,L_ADV*MAX(0,B$5*BTC_Held*$A8/1000000-Debt_Principal-Pref_Notional_Total+Cash_For_EV)/MSTR_Shares*L_Part*Trading_Days) | C8: =IF(AND(Gate_On="Yes",C$5<mNAV_Floor),0,L_ADV*MAX(0,C$5*BTC_Held*$A8/1000000-Debt_Principal-Pref_Notional_Total+Cash_For_EV)/MSTR_Shares*L_Part*Trading_Days) | D8: =IF(AND(Gate_On="Yes",D$5<mNAV_Floor),0,L_ADV*MAX(0,D$5*BTC_Held*$A8/1000000-Debt_Principal-Pref_Notional_Total+Cash_For_EV)/MSTR_Shares*L_Part*Trading_Days) | E8: =IF(AND(Gate_On="Yes",E$5<mNAV_Floor),0,L_ADV*MAX(0,E$5*BTC_Held*$A8/1000000-Debt_Principal-Pref_Notional_Total+Cash_For_EV)/MSTR_Shares*L_Part*Trading_Days) | F8: =IF(AND(Gate_On="Yes",F$5<mNAV_Floor),0,L_ADV*MAX(0,F$5*BTC_Held*$A8/1000000-Debt_Principal-Pref_Notional_Total+Cash_For_EV)/MSTR_Shares*L_Part*Trading_Days) | G8: =IF(AND(Gate_On="Yes",G$5<mNAV_Floor),0,L_ADV*MAX(0,G$5*BTC_Held*$A8/1000000-Debt_Principal-Pref_Notional_Total+Cash_For_EV)/MSTR_Shares*L_Part*Trading_Days) | H8: =IF(AND(Gate_On="Yes",H$5<mNAV_Floor),0,L_ADV*MAX(0,H$5*BTC_Held*$A8/1000000-Debt_Principal-Pref_Notional_Total+Cash_For_EV)/MSTR_Shares*L_Part*Trading_Days)
A9: 60000 | B9: =IF(AND(Gate_On="Yes",B$5<mNAV_Floor),0,L_ADV*MAX(0,B$5*BTC_Held*$A9/1000000-Debt_Principal-Pref_Notional_Total+Cash_For_EV)/MSTR_Shares*L_Part*Trading_Days) | C9: =IF(AND(Gate_On="Yes",C$5<mNAV_Floor),0,L_ADV*MAX(0,C$5*BTC_Held*$A9/1000000-Debt_Principal-Pref_Notional_Total+Cash_For_EV)/MSTR_Shares*L_Part*Trading_Days) | D9: =IF(AND(Gate_On="Yes",D$5<mNAV_Floor),0,L_ADV*MAX(0,D$5*BTC_Held*$A9/1000000-Debt_Principal-Pref_Notional_Total+Cash_For_EV)/MSTR_Shares*L_Part*Trading_Days) | E9: =IF(AND(Gate_On="Yes",E$5<mNAV_Floor),0,L_ADV*MAX(0,E$5*BTC_Held*$A9/1000000-Debt_Principal-Pref_Notional_Total+Cash_For_EV)/MSTR_Shares*L_Part*Trading_Days) | F9: =IF(AND(Gate_On="Yes",F$5<mNAV_Floor),0,L_ADV*MAX(0,F$5*BTC_Held*$A9/1000000-Debt_Principal-Pref_Notional_Total+Cash_For_EV)/MSTR_Shares*L_Part*Trading_Days) | G9: =IF(AND(Gate_On="Yes",G$5<mNAV_Floor),0,L_ADV*MAX(0,G$5*BTC_Held*$A9/1000000-Debt_Principal-Pref_Notional_Total+Cash_For_EV)/MSTR_Shares*L_Part*Trading_Days) | H9: =IF(AND(Gate_On="Yes",H$5<mNAV_Floor),0,L_ADV*MAX(0,H$5*BTC_Held*$A9/1000000-Debt_Principal-Pref_Notional_Total+Cash_For_EV)/MSTR_Shares*L_Part*Trading_Days)
A10: 75000 | B10: =IF(AND(Gate_On="Yes",B$5<mNAV_Floor),0,L_ADV*MAX(0,B$5*BTC_Held*$A10/1000000-Debt_Principal-Pref_Notional_Total+Cash_For_EV)/MSTR_Shares*L_Part*Trading_Days) | C10: =IF(AND(Gate_On="Yes",C$5<mNAV_Floor),0,L_ADV*MAX(0,C$5*BTC_Held*$A10/1000000-Debt_Principal-Pref_Notional_Total+Cash_For_EV)/MSTR_Shares*L_Part*Trading_Days) | D10: =IF(AND(Gate_On="Yes",D$5<mNAV_Floor),0,L_ADV*MAX(0,D$5*BTC_Held*$A10/1000000-Debt_Principal-Pref_Notional_Total+Cash_For_EV)/MSTR_Shares*L_Part*Trading_Days) | E10: =IF(AND(Gate_On="Yes",E$5<mNAV_Floor),0,L_ADV*MAX(0,E$5*BTC_Held*$A10/1000000-Debt_Principal-Pref_Notional_Total+Cash_For_EV)/MSTR_Shares*L_Part*Trading_Days) | F10: =IF(AND(Gate_On="Yes",F$5<mNAV_Floor),0,L_ADV*MAX(0,F$5*BTC_Held*$A10/1000000-Debt_Principal-Pref_Notional_Total+Cash_For_EV)/MSTR_Shares*L_Part*Trading_Days) | G10: =IF(AND(Gate_On="Yes",G$5<mNAV_Floor),0,L_ADV*MAX(0,G$5*BTC_Held*$A10/1000000-Debt_Principal-Pref_Notional_Total+Cash_For_EV)/MSTR_Shares*L_Part*Trading_Days) | H10: =IF(AND(Gate_On="Yes",H$5<mNAV_Floor),0,L_ADV*MAX(0,H$5*BTC_Held*$A10/1000000-Debt_Principal-Pref_Notional_Total+Cash_For_EV)/MSTR_Shares*L_Part*Trading_Days)
A11: 100000 | B11: =IF(AND(Gate_On="Yes",B$5<mNAV_Floor),0,L_ADV*MAX(0,B$5*BTC_Held*$A11/1000000-Debt_Principal-Pref_Notional_Total+Cash_For_EV)/MSTR_Shares*L_Part*Trading_Days) | C11: =IF(AND(Gate_On="Yes",C$5<mNAV_Floor),0,L_ADV*MAX(0,C$5*BTC_Held*$A11/1000000-Debt_Principal-Pref_Notional_Total+Cash_For_EV)/MSTR_Shares*L_Part*Trading_Days) | D11: =IF(AND(Gate_On="Yes",D$5<mNAV_Floor),0,L_ADV*MAX(0,D$5*BTC_Held*$A11/1000000-Debt_Principal-Pref_Notional_Total+Cash_For_EV)/MSTR_Shares*L_Part*Trading_Days) | E11: =IF(AND(Gate_On="Yes",E$5<mNAV_Floor),0,L_ADV*MAX(0,E$5*BTC_Held*$A11/1000000-Debt_Principal-Pref_Notional_Total+Cash_For_EV)/MSTR_Shares*L_Part*Trading_Days) | F11: =IF(AND(Gate_On="Yes",F$5<mNAV_Floor),0,L_ADV*MAX(0,F$5*BTC_Held*$A11/1000000-Debt_Principal-Pref_Notional_Total+Cash_For_EV)/MSTR_Shares*L_Part*Trading_Days) | G11: =IF(AND(Gate_On="Yes",G$5<mNAV_Floor),0,L_ADV*MAX(0,G$5*BTC_Held*$A11/1000000-Debt_Principal-Pref_Notional_Total+Cash_For_EV)/MSTR_Shares*L_Part*Trading_Days) | H11: =IF(AND(Gate_On="Yes",H$5<mNAV_Floor),0,L_ADV*MAX(0,H$5*BTC_Held*$A11/1000000-Debt_Principal-Pref_Notional_Total+Cash_For_EV)/MSTR_Shares*L_Part*Trading_Days)
A12: 125000 | B12: =IF(AND(Gate_On="Yes",B$5<mNAV_Floor),0,L_ADV*MAX(0,B$5*BTC_Held*$A12/1000000-Debt_Principal-Pref_Notional_Total+Cash_For_EV)/MSTR_Shares*L_Part*Trading_Days) | C12: =IF(AND(Gate_On="Yes",C$5<mNAV_Floor),0,L_ADV*MAX(0,C$5*BTC_Held*$A12/1000000-Debt_Principal-Pref_Notional_Total+Cash_For_EV)/MSTR_Shares*L_Part*Trading_Days) | D12: =IF(AND(Gate_On="Yes",D$5<mNAV_Floor),0,L_ADV*MAX(0,D$5*BTC_Held*$A12/1000000-Debt_Principal-Pref_Notional_Total+Cash_For_EV)/MSTR_Shares*L_Part*Trading_Days) | E12: =IF(AND(Gate_On="Yes",E$5<mNAV_Floor),0,L_ADV*MAX(0,E$5*BTC_Held*$A12/1000000-Debt_Principal-Pref_Notional_Total+Cash_For_EV)/MSTR_Shares*L_Part*Trading_Days) | F12: =IF(AND(Gate_On="Yes",F$5<mNAV_Floor),0,L_ADV*MAX(0,F$5*BTC_Held*$A12/1000000-Debt_Principal-Pref_Notional_Total+Cash_For_EV)/MSTR_Shares*L_Part*Trading_Days) | G12: =IF(AND(Gate_On="Yes",G$5<mNAV_Floor),0,L_ADV*MAX(0,G$5*BTC_Held*$A12/1000000-Debt_Principal-Pref_Notional_Total+Cash_For_EV)/MSTR_Shares*L_Part*Trading_Days) | H12: =IF(AND(Gate_On="Yes",H$5<mNAV_Floor),0,L_ADV*MAX(0,H$5*BTC_Held*$A12/1000000-Debt_Principal-Pref_Notional_Total+Cash_For_EV)/MSTR_Shares*L_Part*Trading_Days)
A13: 150000 | B13: =IF(AND(Gate_On="Yes",B$5<mNAV_Floor),0,L_ADV*MAX(0,B$5*BTC_Held*$A13/1000000-Debt_Principal-Pref_Notional_Total+Cash_For_EV)/MSTR_Shares*L_Part*Trading_Days) | C13: =IF(AND(Gate_On="Yes",C$5<mNAV_Floor),0,L_ADV*MAX(0,C$5*BTC_Held*$A13/1000000-Debt_Principal-Pref_Notional_Total+Cash_For_EV)/MSTR_Shares*L_Part*Trading_Days) | D13: =IF(AND(Gate_On="Yes",D$5<mNAV_Floor),0,L_ADV*MAX(0,D$5*BTC_Held*$A13/1000000-Debt_Principal-Pref_Notional_Total+Cash_For_EV)/MSTR_Shares*L_Part*Trading_Days) | E13: =IF(AND(Gate_On="Yes",E$5<mNAV_Floor),0,L_ADV*MAX(0,E$5*BTC_Held*$A13/1000000-Debt_Principal-Pref_Notional_Total+Cash_For_EV)/MSTR_Shares*L_Part*Trading_Days) | F13: =IF(AND(Gate_On="Yes",F$5<mNAV_Floor),0,L_ADV*MAX(0,F$5*BTC_Held*$A13/1000000-Debt_Principal-Pref_Notional_Total+Cash_For_EV)/MSTR_Shares*L_Part*Trading_Days) | G13: =IF(AND(Gate_On="Yes",G$5<mNAV_Floor),0,L_ADV*MAX(0,G$5*BTC_Held*$A13/1000000-Debt_Principal-Pref_Notional_Total+Cash_For_EV)/MSTR_Shares*L_Part*Trading_Days) | H13: =IF(AND(Gate_On="Yes",H$5<mNAV_Floor),0,L_ADV*MAX(0,H$5*BTC_Held*$A13/1000000-Debt_Principal-Pref_Notional_Total+Cash_For_EV)/MSTR_Shares*L_Part*Trading_Days)
A14: 200000 | B14: =IF(AND(Gate_On="Yes",B$5<mNAV_Floor),0,L_ADV*MAX(0,B$5*BTC_Held*$A14/1000000-Debt_Principal-Pref_Notional_Total+Cash_For_EV)/MSTR_Shares*L_Part*Trading_Days) | C14: =IF(AND(Gate_On="Yes",C$5<mNAV_Floor),0,L_ADV*MAX(0,C$5*BTC_Held*$A14/1000000-Debt_Principal-Pref_Notional_Total+Cash_For_EV)/MSTR_Shares*L_Part*Trading_Days) | D14: =IF(AND(Gate_On="Yes",D$5<mNAV_Floor),0,L_ADV*MAX(0,D$5*BTC_Held*$A14/1000000-Debt_Principal-Pref_Notional_Total+Cash_For_EV)/MSTR_Shares*L_Part*Trading_Days) | E14: =IF(AND(Gate_On="Yes",E$5<mNAV_Floor),0,L_ADV*MAX(0,E$5*BTC_Held*$A14/1000000-Debt_Principal-Pref_Notional_Total+Cash_For_EV)/MSTR_Shares*L_Part*Trading_Days) | F14: =IF(AND(Gate_On="Yes",F$5<mNAV_Floor),0,L_ADV*MAX(0,F$5*BTC_Held*$A14/1000000-Debt_Principal-Pref_Notional_Total+Cash_For_EV)/MSTR_Shares*L_Part*Trading_Days) | G14: =IF(AND(Gate_On="Yes",G$5<mNAV_Floor),0,L_ADV*MAX(0,G$5*BTC_Held*$A14/1000000-Debt_Principal-Pref_Notional_Total+Cash_For_EV)/MSTR_Shares*L_Part*Trading_Days) | H14: =IF(AND(Gate_On="Yes",H$5<mNAV_Floor),0,L_ADV*MAX(0,H$5*BTC_Held*$A14/1000000-Debt_Principal-Pref_Notional_Total+Cash_For_EV)/MSTR_Shares*L_Part*Trading_Days)
A15: =BTC_Spot | B15: =IF(AND(Gate_On="Yes",B$5<mNAV_Floor),0,L_ADV*MAX(0,B$5*BTC_Held*$A15/1000000-Debt_Principal-Pref_Notional_Total+Cash_For_EV)/MSTR_Shares*L_Part*Trading_Days) | C15: =IF(AND(Gate_On="Yes",C$5<mNAV_Floor),0,L_ADV*MAX(0,C$5*BTC_Held*$A15/1000000-Debt_Principal-Pref_Notional_Total+Cash_For_EV)/MSTR_Shares*L_Part*Trading_Days) | D15: =IF(AND(Gate_On="Yes",D$5<mNAV_Floor),0,L_ADV*MAX(0,D$5*BTC_Held*$A15/1000000-Debt_Principal-Pref_Notional_Total+Cash_For_EV)/MSTR_Shares*L_Part*Trading_Days) | E15: =IF(AND(Gate_On="Yes",E$5<mNAV_Floor),0,L_ADV*MAX(0,E$5*BTC_Held*$A15/1000000-Debt_Principal-Pref_Notional_Total+Cash_For_EV)/MSTR_Shares*L_Part*Trading_Days) | F15: =IF(AND(Gate_On="Yes",F$5<mNAV_Floor),0,L_ADV*MAX(0,F$5*BTC_Held*$A15/1000000-Debt_Principal-Pref_Notional_Total+Cash_For_EV)/MSTR_Shares*L_Part*Trading_Days) | G15: =IF(AND(Gate_On="Yes",G$5<mNAV_Floor),0,L_ADV*MAX(0,G$5*BTC_Held*$A15/1000000-Debt_Principal-Pref_Notional_Total+Cash_For_EV)/MSTR_Shares*L_Part*Trading_Days) | H15: =IF(AND(Gate_On="Yes",H$5<mNAV_Floor),0,L_ADV*MAX(0,H$5*BTC_Held*$A15/1000000-Debt_Principal-Pref_Notional_Total+Cash_For_EV)/MSTR_Shares*L_Part*Trading_Days)
A16: Zero left of the mNAV floor (the gate). The orange last row is the Base BTC price.
A18: Grid 2. Years of all fixed charges covered by Reserve + common sales
A19: BTC price ↓ mNAV → | B19: 0.6 | C19: 0.8 | D19: 1 | E19: 1.25 | F19: 1.5 | G19: 2 | H19: 2.5
A20: 30000 | B20: =MIN(Display_Cap,IF(AND(B6<Charges_Total,B6*Reserve_Live/(Charges_Total-B6)<=ATM_Cap),Reserve_Live/(Charges_Total-B6),(Reserve_Live+ATM_Cap)/Charges_Total)) | C20: =MIN(Display_Cap,IF(AND(C6<Charges_Total,C6*Reserve_Live/(Charges_Total-C6)<=ATM_Cap),Reserve_Live/(Charges_Total-C6),(Reserve_Live+ATM_Cap)/Charges_Total)) | D20: =MIN(Display_Cap,IF(AND(D6<Charges_Total,D6*Reserve_Live/(Charges_Total-D6)<=ATM_Cap),Reserve_Live/(Charges_Total-D6),(Reserve_Live+ATM_Cap)/Charges_Total)) | E20: =MIN(Display_Cap,IF(AND(E6<Charges_Total,E6*Reserve_Live/(Charges_Total-E6)<=ATM_Cap),Reserve_Live/(Charges_Total-E6),(Reserve_Live+ATM_Cap)/Charges_Total)) | F20: =MIN(Display_Cap,IF(AND(F6<Charges_Total,F6*Reserve_Live/(Charges_Total-F6)<=ATM_Cap),Reserve_Live/(Charges_Total-F6),(Reserve_Live+ATM_Cap)/Charges_Total)) | G20: =MIN(Display_Cap,IF(AND(G6<Charges_Total,G6*Reserve_Live/(Charges_Total-G6)<=ATM_Cap),Reserve_Live/(Charges_Total-G6),(Reserve_Live+ATM_Cap)/Charges_Total)) | H20: =MIN(Display_Cap,IF(AND(H6<Charges_Total,H6*Reserve_Live/(Charges_Total-H6)<=ATM_Cap),Reserve_Live/(Charges_Total-H6),(Reserve_Live+ATM_Cap)/Charges_Total))
A21: 40000 | B21: =MIN(Display_Cap,IF(AND(B7<Charges_Total,B7*Reserve_Live/(Charges_Total-B7)<=ATM_Cap),Reserve_Live/(Charges_Total-B7),(Reserve_Live+ATM_Cap)/Charges_Total)) | C21: =MIN(Display_Cap,IF(AND(C7<Charges_Total,C7*Reserve_Live/(Charges_Total-C7)<=ATM_Cap),Reserve_Live/(Charges_Total-C7),(Reserve_Live+ATM_Cap)/Charges_Total)) | D21: =MIN(Display_Cap,IF(AND(D7<Charges_Total,D7*Reserve_Live/(Charges_Total-D7)<=ATM_Cap),Reserve_Live/(Charges_Total-D7),(Reserve_Live+ATM_Cap)/Charges_Total)) | E21: =MIN(Display_Cap,IF(AND(E7<Charges_Total,E7*Reserve_Live/(Charges_Total-E7)<=ATM_Cap),Reserve_Live/(Charges_Total-E7),(Reserve_Live+ATM_Cap)/Charges_Total)) | F21: =MIN(Display_Cap,IF(AND(F7<Charges_Total,F7*Reserve_Live/(Charges_Total-F7)<=ATM_Cap),Reserve_Live/(Charges_Total-F7),(Reserve_Live+ATM_Cap)/Charges_Total)) | G21: =MIN(Display_Cap,IF(AND(G7<Charges_Total,G7*Reserve_Live/(Charges_Total-G7)<=ATM_Cap),Reserve_Live/(Charges_Total-G7),(Reserve_Live+ATM_Cap)/Charges_Total)) | H21: =MIN(Display_Cap,IF(AND(H7<Charges_Total,H7*Reserve_Live/(Charges_Total-H7)<=ATM_Cap),Reserve_Live/(Charges_Total-H7),(Reserve_Live+ATM_Cap)/Charges_Total))
A22: 50000 | B22: =MIN(Display_Cap,IF(AND(B8<Charges_Total,B8*Reserve_Live/(Charges_Total-B8)<=ATM_Cap),Reserve_Live/(Charges_Total-B8),(Reserve_Live+ATM_Cap)/Charges_Total)) | C22: =MIN(Display_Cap,IF(AND(C8<Charges_Total,C8*Reserve_Live/(Charges_Total-C8)<=ATM_Cap),Reserve_Live/(Charges_Total-C8),(Reserve_Live+ATM_Cap)/Charges_Total)) | D22: =MIN(Display_Cap,IF(AND(D8<Charges_Total,D8*Reserve_Live/(Charges_Total-D8)<=ATM_Cap),Reserve_Live/(Charges_Total-D8),(Reserve_Live+ATM_Cap)/Charges_Total)) | E22: =MIN(Display_Cap,IF(AND(E8<Charges_Total,E8*Reserve_Live/(Charges_Total-E8)<=ATM_Cap),Reserve_Live/(Charges_Total-E8),(Reserve_Live+ATM_Cap)/Charges_Total)) | F22: =MIN(Display_Cap,IF(AND(F8<Charges_Total,F8*Reserve_Live/(Charges_Total-F8)<=ATM_Cap),Reserve_Live/(Charges_Total-F8),(Reserve_Live+ATM_Cap)/Charges_Total)) | G22: =MIN(Display_Cap,IF(AND(G8<Charges_Total,G8*Reserve_Live/(Charges_Total-G8)<=ATM_Cap),Reserve_Live/(Charges_Total-G8),(Reserve_Live+ATM_Cap)/Charges_Total)) | H22: =MIN(Display_Cap,IF(AND(H8<Charges_Total,H8*Reserve_Live/(Charges_Total-H8)<=ATM_Cap),Reserve_Live/(Charges_Total-H8),(Reserve_Live+ATM_Cap)/Charges_Total))
A23: 60000 | B23: =MIN(Display_Cap,IF(AND(B9<Charges_Total,B9*Reserve_Live/(Charges_Total-B9)<=ATM_Cap),Reserve_Live/(Charges_Total-B9),(Reserve_Live+ATM_Cap)/Charges_Total)) | C23: =MIN(Display_Cap,IF(AND(C9<Charges_Total,C9*Reserve_Live/(Charges_Total-C9)<=ATM_Cap),Reserve_Live/(Charges_Total-C9),(Reserve_Live+ATM_Cap)/Charges_Total)) | D23: =MIN(Display_Cap,IF(AND(D9<Charges_Total,D9*Reserve_Live/(Charges_Total-D9)<=ATM_Cap),Reserve_Live/(Charges_Total-D9),(Reserve_Live+ATM_Cap)/Charges_Total)) | E23: =MIN(Display_Cap,IF(AND(E9<Charges_Total,E9*Reserve_Live/(Charges_Total-E9)<=ATM_Cap),Reserve_Live/(Charges_Total-E9),(Reserve_Live+ATM_Cap)/Charges_Total)) | F23: =MIN(Display_Cap,IF(AND(F9<Charges_Total,F9*Reserve_Live/(Charges_Total-F9)<=ATM_Cap),Reserve_Live/(Charges_Total-F9),(Reserve_Live+ATM_Cap)/Charges_Total)) | G23: =MIN(Display_Cap,IF(AND(G9<Charges_Total,G9*Reserve_Live/(Charges_Total-G9)<=ATM_Cap),Reserve_Live/(Charges_Total-G9),(Reserve_Live+ATM_Cap)/Charges_Total)) | H23: =MIN(Display_Cap,IF(AND(H9<Charges_Total,H9*Reserve_Live/(Charges_Total-H9)<=ATM_Cap),Reserve_Live/(Charges_Total-H9),(Reserve_Live+ATM_Cap)/Charges_Total))
A24: 75000 | B24: =MIN(Display_Cap,IF(AND(B10<Charges_Total,B10*Reserve_Live/(Charges_Total-B10)<=ATM_Cap),Reserve_Live/(Charges_Total-B10),(Reserve_Live+ATM_Cap)/Charges_Total)) | C24: =MIN(Display_Cap,IF(AND(C10<Charges_Total,C10*Reserve_Live/(Charges_Total-C10)<=ATM_Cap),Reserve_Live/(Charges_Total-C10),(Reserve_Live+ATM_Cap)/Charges_Total)) | D24: =MIN(Display_Cap,IF(AND(D10<Charges_Total,D10*Reserve_Live/(Charges_Total-D10)<=ATM_Cap),Reserve_Live/(Charges_Total-D10),(Reserve_Live+ATM_Cap)/Charges_Total)) | E24: =MIN(Display_Cap,IF(AND(E10<Charges_Total,E10*Reserve_Live/(Charges_Total-E10)<=ATM_Cap),Reserve_Live/(Charges_Total-E10),(Reserve_Live+ATM_Cap)/Charges_Total)) | F24: =MIN(Display_Cap,IF(AND(F10<Charges_Total,F10*Reserve_Live/(Charges_Total-F10)<=ATM_Cap),Reserve_Live/(Charges_Total-F10),(Reserve_Live+ATM_Cap)/Charges_Total)) | G24: =MIN(Display_Cap,IF(AND(G10<Charges_Total,G10*Reserve_Live/(Charges_Total-G10)<=ATM_Cap),Reserve_Live/(Charges_Total-G10),(Reserve_Live+ATM_Cap)/Charges_Total)) | H24: =MIN(Display_Cap,IF(AND(H10<Charges_Total,H10*Reserve_Live/(Charges_Total-H10)<=ATM_Cap),Reserve_Live/(Charges_Total-H10),(Reserve_Live+ATM_Cap)/Charges_Total))
A25: 100000 | B25: =MIN(Display_Cap,IF(AND(B11<Charges_Total,B11*Reserve_Live/(Charges_Total-B11)<=ATM_Cap),Reserve_Live/(Charges_Total-B11),(Reserve_Live+ATM_Cap)/Charges_Total)) | C25: =MIN(Display_Cap,IF(AND(C11<Charges_Total,C11*Reserve_Live/(Charges_Total-C11)<=ATM_Cap),Reserve_Live/(Charges_Total-C11),(Reserve_Live+ATM_Cap)/Charges_Total)) | D25: =MIN(Display_Cap,IF(AND(D11<Charges_Total,D11*Reserve_Live/(Charges_Total-D11)<=ATM_Cap),Reserve_Live/(Charges_Total-D11),(Reserve_Live+ATM_Cap)/Charges_Total)) | E25: =MIN(Display_Cap,IF(AND(E11<Charges_Total,E11*Reserve_Live/(Charges_Total-E11)<=ATM_Cap),Reserve_Live/(Charges_Total-E11),(Reserve_Live+ATM_Cap)/Charges_Total)) | F25: =MIN(Display_Cap,IF(AND(F11<Charges_Total,F11*Reserve_Live/(Charges_Total-F11)<=ATM_Cap),Reserve_Live/(Charges_Total-F11),(Reserve_Live+ATM_Cap)/Charges_Total)) | G25: =MIN(Display_Cap,IF(AND(G11<Charges_Total,G11*Reserve_Live/(Charges_Total-G11)<=ATM_Cap),Reserve_Live/(Charges_Total-G11),(Reserve_Live+ATM_Cap)/Charges_Total)) | H25: =MIN(Display_Cap,IF(AND(H11<Charges_Total,H11*Reserve_Live/(Charges_Total-H11)<=ATM_Cap),Reserve_Live/(Charges_Total-H11),(Reserve_Live+ATM_Cap)/Charges_Total))
A26: 125000 | B26: =MIN(Display_Cap,IF(AND(B12<Charges_Total,B12*Reserve_Live/(Charges_Total-B12)<=ATM_Cap),Reserve_Live/(Charges_Total-B12),(Reserve_Live+ATM_Cap)/Charges_Total)) | C26: =MIN(Display_Cap,IF(AND(C12<Charges_Total,C12*Reserve_Live/(Charges_Total-C12)<=ATM_Cap),Reserve_Live/(Charges_Total-C12),(Reserve_Live+ATM_Cap)/Charges_Total)) | D26: =MIN(Display_Cap,IF(AND(D12<Charges_Total,D12*Reserve_Live/(Charges_Total-D12)<=ATM_Cap),Reserve_Live/(Charges_Total-D12),(Reserve_Live+ATM_Cap)/Charges_Total)) | E26: =MIN(Display_Cap,IF(AND(E12<Charges_Total,E12*Reserve_Live/(Charges_Total-E12)<=ATM_Cap),Reserve_Live/(Charges_Total-E12),(Reserve_Live+ATM_Cap)/Charges_Total)) | F26: =MIN(Display_Cap,IF(AND(F12<Charges_Total,F12*Reserve_Live/(Charges_Total-F12)<=ATM_Cap),Reserve_Live/(Charges_Total-F12),(Reserve_Live+ATM_Cap)/Charges_Total)) | G26: =MIN(Display_Cap,IF(AND(G12<Charges_Total,G12*Reserve_Live/(Charges_Total-G12)<=ATM_Cap),Reserve_Live/(Charges_Total-G12),(Reserve_Live+ATM_Cap)/Charges_Total)) | H26: =MIN(Display_Cap,IF(AND(H12<Charges_Total,H12*Reserve_Live/(Charges_Total-H12)<=ATM_Cap),Reserve_Live/(Charges_Total-H12),(Reserve_Live+ATM_Cap)/Charges_Total))
A27: 150000 | B27: =MIN(Display_Cap,IF(AND(B13<Charges_Total,B13*Reserve_Live/(Charges_Total-B13)<=ATM_Cap),Reserve_Live/(Charges_Total-B13),(Reserve_Live+ATM_Cap)/Charges_Total)) | C27: =MIN(Display_Cap,IF(AND(C13<Charges_Total,C13*Reserve_Live/(Charges_Total-C13)<=ATM_Cap),Reserve_Live/(Charges_Total-C13),(Reserve_Live+ATM_Cap)/Charges_Total)) | D27: =MIN(Display_Cap,IF(AND(D13<Charges_Total,D13*Reserve_Live/(Charges_Total-D13)<=ATM_Cap),Reserve_Live/(Charges_Total-D13),(Reserve_Live+ATM_Cap)/Charges_Total)) | E27: =MIN(Display_Cap,IF(AND(E13<Charges_Total,E13*Reserve_Live/(Charges_Total-E13)<=ATM_Cap),Reserve_Live/(Charges_Total-E13),(Reserve_Live+ATM_Cap)/Charges_Total)) | F27: =MIN(Display_Cap,IF(AND(F13<Charges_Total,F13*Reserve_Live/(Charges_Total-F13)<=ATM_Cap),Reserve_Live/(Charges_Total-F13),(Reserve_Live+ATM_Cap)/Charges_Total)) | G27: =MIN(Display_Cap,IF(AND(G13<Charges_Total,G13*Reserve_Live/(Charges_Total-G13)<=ATM_Cap),Reserve_Live/(Charges_Total-G13),(Reserve_Live+ATM_Cap)/Charges_Total)) | H27: =MIN(Display_Cap,IF(AND(H13<Charges_Total,H13*Reserve_Live/(Charges_Total-H13)<=ATM_Cap),Reserve_Live/(Charges_Total-H13),(Reserve_Live+ATM_Cap)/Charges_Total))
A28: 200000 | B28: =MIN(Display_Cap,IF(AND(B14<Charges_Total,B14*Reserve_Live/(Charges_Total-B14)<=ATM_Cap),Reserve_Live/(Charges_Total-B14),(Reserve_Live+ATM_Cap)/Charges_Total)) | C28: =MIN(Display_Cap,IF(AND(C14<Charges_Total,C14*Reserve_Live/(Charges_Total-C14)<=ATM_Cap),Reserve_Live/(Charges_Total-C14),(Reserve_Live+ATM_Cap)/Charges_Total)) | D28: =MIN(Display_Cap,IF(AND(D14<Charges_Total,D14*Reserve_Live/(Charges_Total-D14)<=ATM_Cap),Reserve_Live/(Charges_Total-D14),(Reserve_Live+ATM_Cap)/Charges_Total)) | E28: =MIN(Display_Cap,IF(AND(E14<Charges_Total,E14*Reserve_Live/(Charges_Total-E14)<=ATM_Cap),Reserve_Live/(Charges_Total-E14),(Reserve_Live+ATM_Cap)/Charges_Total)) | F28: =MIN(Display_Cap,IF(AND(F14<Charges_Total,F14*Reserve_Live/(Charges_Total-F14)<=ATM_Cap),Reserve_Live/(Charges_Total-F14),(Reserve_Live+ATM_Cap)/Charges_Total)) | G28: =MIN(Display_Cap,IF(AND(G14<Charges_Total,G14*Reserve_Live/(Charges_Total-G14)<=ATM_Cap),Reserve_Live/(Charges_Total-G14),(Reserve_Live+ATM_Cap)/Charges_Total)) | H28: =MIN(Display_Cap,IF(AND(H14<Charges_Total,H14*Reserve_Live/(Charges_Total-H14)<=ATM_Cap),Reserve_Live/(Charges_Total-H14),(Reserve_Live+ATM_Cap)/Charges_Total))
